ERROR:root:something bad happened
Traceback (most recent call last):
  File "paper_trade.py", line 136, in <module>
    dps_model_pos=get_dps_model_pos(dpsList.keys())
  File "C:\cygwin64\media\sf_Python\TSDP\seitoolz\signal.py", line 33, in get_dps_model_pos
    data = pd.read_csv(filename, index_col='dates')
  File "C:\Anaconda2\lib\site-packages\pandas\io\parsers.py", line 498, in parser_f
    return _read(filepath_or_buffer, kwds)
  File "C:\Anaconda2\lib\site-packages\pandas\io\parsers.py", line 275, in _read
    parser = TextFileReader(filepath_or_buffer, **kwds)
  File "C:\Anaconda2\lib\site-packages\pandas\io\parsers.py", line 590, in __init__
    self._make_engine(self.engine)
  File "C:\Anaconda2\lib\site-packages\pandas\io\parsers.py", line 731, in _make_engine
    self._engine = CParserWrapper(self.f, **self.options)
  File "C:\Anaconda2\lib\site-packages\pandas\io\parsers.py", line 1103, in __init__
    self._reader = _parser.TextReader(src, **kwds)
  File "pandas\parser.pyx", line 518, in pandas.parser.TextReader.__cinit__ (pandas\parser.c:5030)
ValueError: No columns to parse from file
ERROR:root:something bad happened
Traceback (most recent call last):
  File "paper_trade.py", line 136, in <module>
    dps_model_pos=get_dps_model_pos(dpsList.keys())
  File "C:\cygwin64\media\sf_Python\TSDP\seitoolz\signal.py", line 33, in get_dps_model_pos
    data = pd.read_csv(filename, index_col='dates')
  File "C:\Anaconda2\lib\site-packages\pandas\io\parsers.py", line 498, in parser_f
    return _read(filepath_or_buffer, kwds)
  File "C:\Anaconda2\lib\site-packages\pandas\io\parsers.py", line 275, in _read
    parser = TextFileReader(filepath_or_buffer, **kwds)
  File "C:\Anaconda2\lib\site-packages\pandas\io\parsers.py", line 590, in __init__
    self._make_engine(self.engine)
  File "C:\Anaconda2\lib\site-packages\pandas\io\parsers.py", line 731, in _make_engine
    self._engine = CParserWrapper(self.f, **self.options)
  File "C:\Anaconda2\lib\site-packages\pandas\io\parsers.py", line 1103, in __init__
    self._reader = _parser.TextReader(src, **kwds)
  File "pandas\parser.pyx", line 518, in pandas.parser.TextReader.__cinit__ (pandas\parser.c:5030)
ValueError: No columns to parse from file
ERROR:root:something bad happened
Traceback (most recent call last):
  File "paper_trade.py", line 136, in <module>
    dps_model_pos=get_dps_model_pos(dpsList.keys())
  File "C:\cygwin64\media\sf_Python\TSDP\seitoolz\signal.py", line 33, in get_dps_model_pos
    data = pd.read_csv(filename, index_col='dates')
  File "C:\Anaconda2\lib\site-packages\pandas\io\parsers.py", line 498, in parser_f
    return _read(filepath_or_buffer, kwds)
  File "C:\Anaconda2\lib\site-packages\pandas\io\parsers.py", line 275, in _read
    parser = TextFileReader(filepath_or_buffer, **kwds)
  File "C:\Anaconda2\lib\site-packages\pandas\io\parsers.py", line 590, in __init__
    self._make_engine(self.engine)
  File "C:\Anaconda2\lib\site-packages\pandas\io\parsers.py", line 731, in _make_engine
    self._engine = CParserWrapper(self.f, **self.options)
  File "C:\Anaconda2\lib\site-packages\pandas\io\parsers.py", line 1103, in __init__
    self._reader = _parser.TextReader(src, **kwds)
  File "pandas\parser.pyx", line 518, in pandas.parser.TextReader.__cinit__ (pandas\parser.c:5030)
ValueError: No columns to parse from file
ERROR:root:something bad happened
Traceback (most recent call last):
  File "paper_trade.py", line 136, in <module>
    dps_model_pos=get_dps_model_pos(dpsList.keys())
  File "C:\cygwin64\media\sf_Python\TSDP\seitoolz\signal.py", line 33, in get_dps_model_pos
    data = pd.read_csv(filename, index_col='dates')
  File "C:\Anaconda2\lib\site-packages\pandas\io\parsers.py", line 498, in parser_f
    return _read(filepath_or_buffer, kwds)
  File "C:\Anaconda2\lib\site-packages\pandas\io\parsers.py", line 275, in _read
    parser = TextFileReader(filepath_or_buffer, **kwds)
  File "C:\Anaconda2\lib\site-packages\pandas\io\parsers.py", line 590, in __init__
    self._make_engine(self.engine)
  File "C:\Anaconda2\lib\site-packages\pandas\io\parsers.py", line 731, in _make_engine
    self._engine = CParserWrapper(self.f, **self.options)
  File "C:\Anaconda2\lib\site-packages\pandas\io\parsers.py", line 1103, in __init__
    self._reader = _parser.TextReader(src, **kwds)
  File "pandas\parser.pyx", line 518, in pandas.parser.TextReader.__cinit__ (pandas\parser.c:5030)
ValueError: No columns to parse from file
ERROR:root:something bad happened
Traceback (most recent call last):
  File "paper_trade.py", line 136, in <module>
    dps_model_pos=get_dps_model_pos(dpsList.keys())
  File "C:\cygwin64\media\sf_Python\TSDP\seitoolz\signal.py", line 33, in get_dps_model_pos
    data = pd.read_csv(filename, index_col='dates')
  File "C:\Anaconda2\lib\site-packages\pandas\io\parsers.py", line 498, in parser_f
    return _read(filepath_or_buffer, kwds)
  File "C:\Anaconda2\lib\site-packages\pandas\io\parsers.py", line 275, in _read
    parser = TextFileReader(filepath_or_buffer, **kwds)
  File "C:\Anaconda2\lib\site-packages\pandas\io\parsers.py", line 590, in __init__
    self._make_engine(self.engine)
  File "C:\Anaconda2\lib\site-packages\pandas\io\parsers.py", line 731, in _make_engine
    self._engine = CParserWrapper(self.f, **self.options)
  File "C:\Anaconda2\lib\site-packages\pandas\io\parsers.py", line 1103, in __init__
    self._reader = _parser.TextReader(src, **kwds)
  File "pandas\parser.pyx", line 518, in pandas.parser.TextReader.__cinit__ (pandas\parser.c:5030)
ValueError: No columns to parse from file
ERROR:root:something bad happened
Traceback (most recent call last):
  File "paper_trade.py", line 136, in <module>
    dps_model_pos=get_dps_model_pos(dpsList.keys())
  File "C:\cygwin64\media\sf_Python\TSDP\seitoolz\signal.py", line 33, in get_dps_model_pos
    data = pd.read_csv(filename, index_col='dates')
  File "C:\Anaconda2\lib\site-packages\pandas\io\parsers.py", line 498, in parser_f
    return _read(filepath_or_buffer, kwds)
  File "C:\Anaconda2\lib\site-packages\pandas\io\parsers.py", line 275, in _read
    parser = TextFileReader(filepath_or_buffer, **kwds)
  File "C:\Anaconda2\lib\site-packages\pandas\io\parsers.py", line 590, in __init__
    self._make_engine(self.engine)
  File "C:\Anaconda2\lib\site-packages\pandas\io\parsers.py", line 731, in _make_engine
    self._engine = CParserWrapper(self.f, **self.options)
  File "C:\Anaconda2\lib\site-packages\pandas\io\parsers.py", line 1103, in __init__
    self._reader = _parser.TextReader(src, **kwds)
  File "pandas\parser.pyx", line 518, in pandas.parser.TextReader.__cinit__ (pandas\parser.c:5030)
ValueError: No columns to parse from file
